[2025-09-01T13:36:54.070+0000] {logging_mixin.py:150} WARNING - /home/***/.local/lib/python3.7/site-packages/***/utils/sqlalchemy.py:124 DeprecationWarning: The sql_alchemy_conn option in [core] has been moved to the sql_alchemy_conn option in [database] - the old setting has been used, but please update your config.
[2025-09-01T13:36:54.204+0000] {taskinstance.py:1103} INFO - Dependencies all met for dep_context=non-requeueable deps ti=<TaskInstance: kafka_to_postgres.consume_and_save scheduled__2025-09-01T13:30:00+00:00 [queued]>
[2025-09-01T13:36:54.285+0000] {taskinstance.py:1103} INFO - Dependencies all met for dep_context=requeueable deps ti=<TaskInstance: kafka_to_postgres.consume_and_save scheduled__2025-09-01T13:30:00+00:00 [queued]>
[2025-09-01T13:36:54.288+0000] {taskinstance.py:1308} INFO - Starting attempt 3 of 3
[2025-09-01T13:36:54.436+0000] {taskinstance.py:1327} INFO - Executing <Task(PythonOperator): consume_and_save> on 2025-09-01 13:30:00+00:00
[2025-09-01T13:36:54.510+0000] {standard_task_runner.py:57} INFO - Started process 474 to run task
[2025-09-01T13:36:54.539+0000] {standard_task_runner.py:84} INFO - Running: ['***', 'tasks', 'run', 'kafka_to_postgres', 'consume_and_save', 'scheduled__2025-09-01T13:30:00+00:00', '--job-id', '25', '--raw', '--subdir', 'DAGS_FOLDER/dags.py', '--cfg-path', '/tmp/tmp9s7ys879']
[2025-09-01T13:36:54.548+0000] {standard_task_runner.py:85} INFO - Job 25: Subtask consume_and_save
[2025-09-01T13:36:54.690+0000] {logging_mixin.py:150} WARNING - /home/***/.local/lib/python3.7/site-packages/***/settings.py:195 DeprecationWarning: The sql_alchemy_conn option in [core] has been moved to the sql_alchemy_conn option in [database] - the old setting has been used, but please update your config.
[2025-09-01T13:36:55.004+0000] {task_command.py:410} INFO - Running <TaskInstance: kafka_to_postgres.consume_and_save scheduled__2025-09-01T13:30:00+00:00 [running]> on host 09bf1d5cefac
[2025-09-01T13:36:55.094+0000] {logging_mixin.py:150} WARNING - /home/***/.local/lib/python3.7/site-packages/***/utils/sqlalchemy.py:124 DeprecationWarning: The sql_alchemy_conn option in [core] has been moved to the sql_alchemy_conn option in [database] - the old setting has been used, but please update your config.
[2025-09-01T13:36:55.842+0000] {taskinstance.py:1547} INFO - Exporting env vars: AIRFLOW_CTX_DAG_OWNER='***' AIRFLOW_CTX_DAG_ID='kafka_to_postgres' AIRFLOW_CTX_TASK_ID='consume_and_save' AIRFLOW_CTX_EXECUTION_DATE='2025-09-01T13:30:00+00:00' AIRFLOW_CTX_TRY_NUMBER='3' AIRFLOW_CTX_DAG_RUN_ID='scheduled__2025-09-01T13:30:00+00:00'
[2025-09-01T13:37:03.876+0000] {conn.py:1521} WARNING - DNS lookup failed for kafka:9092, exception was [Errno -3] Temporary failure in name resolution. Is your advertised.listeners (called advertised.host.name before Kafka 9) correct and resolvable?
[2025-09-01T13:37:03.877+0000] {conn.py:324} ERROR - <BrokerConnection client_id=kafka-python-2.2.15, node_id=bootstrap-0 host=kafka:9092 <connecting> [unspecified None]>: DNS lookup failed for kafka:9092 (AddressFamily.AF_UNSPEC)
[2025-09-01T13:37:03.882+0000] {conn.py:945} ERROR - <BrokerConnection client_id=kafka-python-2.2.15, node_id=bootstrap-0 host=kafka:9092 <connecting> [unspecified None]>: Closing connection. KafkaConnectionError: DNS failure
[2025-09-01T13:37:03.892+0000] {taskinstance.py:1824} ERROR - Task failed with exception
Traceback (most recent call last):
  File "/home/airflow/.local/lib/python3.7/site-packages/airflow/operators/python.py", line 181, in execute
    return_value = self.execute_callable()
  File "/home/airflow/.local/lib/python3.7/site-packages/airflow/operators/python.py", line 198, in execute_callable
    return self.python_callable(*self.op_args, **self.op_kwargs)
  File "/opt/airflow/dags/dags_utils.py", line 26, in consume_and_save
    group_id="airflow_consumer"
  File "/home/airflow/.local/lib/python3.7/site-packages/kafka/consumer/group.py", line 387, in __init__
    self._client = self.config['kafka_client'](metrics=self._metrics, **self.config)
  File "/home/airflow/.local/lib/python3.7/site-packages/kafka/client_async.py", line 262, in __init__
    self.config['api_version'] = self.check_version()
  File "/home/airflow/.local/lib/python3.7/site-packages/kafka/client_async.py", line 1074, in check_version
    raise Errors.NoBrokersAvailable()
kafka.errors.NoBrokersAvailable: NoBrokersAvailable
[2025-09-01T13:37:04.084+0000] {taskinstance.py:1350} INFO - Marking task as FAILED. dag_id=kafka_to_postgres, task_id=consume_and_save, execution_date=20250901T133000, start_date=20250901T133654, end_date=20250901T133704
[2025-09-01T13:37:04.303+0000] {standard_task_runner.py:109} ERROR - Failed to execute job 25 for task consume_and_save (NoBrokersAvailable; 474)
[2025-09-01T13:37:04.416+0000] {local_task_job_runner.py:225} INFO - Task exited with return code 1
[2025-09-01T13:37:04.550+0000] {taskinstance.py:2653} INFO - 0 downstream tasks scheduled from follow-on schedule check
