[2025-09-01T13:35:01.452+0000] {logging_mixin.py:150} WARNING - /home/***/.local/lib/python3.7/site-packages/***/utils/sqlalchemy.py:124 DeprecationWarning: The sql_alchemy_conn option in [core] has been moved to the sql_alchemy_conn option in [database] - the old setting has been used, but please update your config.
[2025-09-01T13:35:01.466+0000] {taskinstance.py:1103} INFO - Dependencies all met for dep_context=non-requeueable deps ti=<TaskInstance: kafka_to_postgres.consume_and_save scheduled__2025-09-01T13:30:00+00:00 [queued]>
[2025-09-01T13:35:01.477+0000] {taskinstance.py:1103} INFO - Dependencies all met for dep_context=requeueable deps ti=<TaskInstance: kafka_to_postgres.consume_and_save scheduled__2025-09-01T13:30:00+00:00 [queued]>
[2025-09-01T13:35:01.478+0000] {taskinstance.py:1308} INFO - Starting attempt 1 of 3
[2025-09-01T13:35:01.502+0000] {taskinstance.py:1327} INFO - Executing <Task(PythonOperator): consume_and_save> on 2025-09-01 13:30:00+00:00
[2025-09-01T13:35:01.508+0000] {standard_task_runner.py:57} INFO - Started process 425 to run task
[2025-09-01T13:35:01.532+0000] {standard_task_runner.py:84} INFO - Running: ['***', 'tasks', 'run', 'kafka_to_postgres', 'consume_and_save', 'scheduled__2025-09-01T13:30:00+00:00', '--job-id', '21', '--raw', '--subdir', 'DAGS_FOLDER/dags.py', '--cfg-path', '/tmp/tmpm_m1casw']
[2025-09-01T13:35:01.536+0000] {standard_task_runner.py:85} INFO - Job 21: Subtask consume_and_save
[2025-09-01T13:35:01.563+0000] {logging_mixin.py:150} WARNING - /home/***/.local/lib/python3.7/site-packages/***/settings.py:195 DeprecationWarning: The sql_alchemy_conn option in [core] has been moved to the sql_alchemy_conn option in [database] - the old setting has been used, but please update your config.
[2025-09-01T13:35:01.622+0000] {task_command.py:410} INFO - Running <TaskInstance: kafka_to_postgres.consume_and_save scheduled__2025-09-01T13:30:00+00:00 [running]> on host 09bf1d5cefac
[2025-09-01T13:35:01.643+0000] {logging_mixin.py:150} WARNING - /home/***/.local/lib/python3.7/site-packages/***/utils/sqlalchemy.py:124 DeprecationWarning: The sql_alchemy_conn option in [core] has been moved to the sql_alchemy_conn option in [database] - the old setting has been used, but please update your config.
[2025-09-01T13:35:01.773+0000] {taskinstance.py:1547} INFO - Exporting env vars: AIRFLOW_CTX_DAG_OWNER='***' AIRFLOW_CTX_DAG_ID='kafka_to_postgres' AIRFLOW_CTX_TASK_ID='consume_and_save' AIRFLOW_CTX_EXECUTION_DATE='2025-09-01T13:30:00+00:00' AIRFLOW_CTX_TRY_NUMBER='1' AIRFLOW_CTX_DAG_RUN_ID='scheduled__2025-09-01T13:30:00+00:00'
[2025-09-01T13:35:09.783+0000] {conn.py:1521} WARNING - DNS lookup failed for kafka:9092, exception was [Errno -3] Temporary failure in name resolution. Is your advertised.listeners (called advertised.host.name before Kafka 9) correct and resolvable?
[2025-09-01T13:35:09.784+0000] {conn.py:324} ERROR - <BrokerConnection client_id=kafka-python-2.2.15, node_id=bootstrap-0 host=kafka:9092 <connecting> [unspecified None]>: DNS lookup failed for kafka:9092 (AddressFamily.AF_UNSPEC)
[2025-09-01T13:35:09.785+0000] {conn.py:945} ERROR - <BrokerConnection client_id=kafka-python-2.2.15, node_id=bootstrap-0 host=kafka:9092 <connecting> [unspecified None]>: Closing connection. KafkaConnectionError: DNS failure
[2025-09-01T13:35:09.787+0000] {taskinstance.py:1824} ERROR - Task failed with exception
Traceback (most recent call last):
  File "/home/airflow/.local/lib/python3.7/site-packages/airflow/operators/python.py", line 181, in execute
    return_value = self.execute_callable()
  File "/home/airflow/.local/lib/python3.7/site-packages/airflow/operators/python.py", line 198, in execute_callable
    return self.python_callable(*self.op_args, **self.op_kwargs)
  File "/opt/airflow/dags/dags_utils.py", line 26, in consume_and_save
    group_id="airflow_consumer"
  File "/home/airflow/.local/lib/python3.7/site-packages/kafka/consumer/group.py", line 387, in __init__
    self._client = self.config['kafka_client'](metrics=self._metrics, **self.config)
  File "/home/airflow/.local/lib/python3.7/site-packages/kafka/client_async.py", line 262, in __init__
    self.config['api_version'] = self.check_version()
  File "/home/airflow/.local/lib/python3.7/site-packages/kafka/client_async.py", line 1074, in check_version
    raise Errors.NoBrokersAvailable()
kafka.errors.NoBrokersAvailable: NoBrokersAvailable
[2025-09-01T13:35:09.805+0000] {taskinstance.py:1350} INFO - Marking task as UP_FOR_RETRY. dag_id=kafka_to_postgres, task_id=consume_and_save, execution_date=20250901T133000, start_date=20250901T133501, end_date=20250901T133509
[2025-09-01T13:35:09.825+0000] {standard_task_runner.py:109} ERROR - Failed to execute job 21 for task consume_and_save (NoBrokersAvailable; 425)
[2025-09-01T13:35:09.859+0000] {local_task_job_runner.py:225} INFO - Task exited with return code 1
[2025-09-01T13:35:09.885+0000] {taskinstance.py:2653} INFO - 0 downstream tasks scheduled from follow-on schedule check
