[2025-09-01T13:36:08.932+0000] {taskinstance.py:1103} INFO - Dependencies all met for dep_context=non-requeueable deps ti=<TaskInstance: kafka_to_postgres.consume_and_save manual__2025-09-01T13:35:19.051238+00:00 [queued]>
[2025-09-01T13:36:09.114+0000] {taskinstance.py:1103} INFO - Dependencies all met for dep_context=requeueable deps ti=<TaskInstance: kafka_to_postgres.consume_and_save manual__2025-09-01T13:35:19.051238+00:00 [queued]>
[2025-09-01T13:36:09.184+0000] {taskinstance.py:1308} INFO - Starting attempt 2 of 3
[2025-09-01T13:36:10.048+0000] {taskinstance.py:1327} INFO - Executing <Task(PythonOperator): consume_and_save> on 2025-09-01 13:35:19.051238+00:00
[2025-09-01T13:36:10.168+0000] {standard_task_runner.py:57} INFO - Started process 451 to run task
[2025-09-01T13:36:10.294+0000] {standard_task_runner.py:84} INFO - Running: ['***', 'tasks', 'run', 'kafka_to_postgres', 'consume_and_save', 'manual__2025-09-01T13:35:19.051238+00:00', '--job-id', '24', '--raw', '--subdir', 'DAGS_FOLDER/dags.py', '--cfg-path', '/tmp/tmp07i3e66u']
[2025-09-01T13:36:10.328+0000] {standard_task_runner.py:85} INFO - Job 24: Subtask consume_and_save
[2025-09-01T13:36:10.706+0000] {logging_mixin.py:150} WARNING - /home/***/.local/lib/python3.7/site-packages/***/settings.py:195 DeprecationWarning: The sql_alchemy_conn option in [core] has been moved to the sql_alchemy_conn option in [database] - the old setting has been used, but please update your config.
[2025-09-01T13:36:11.437+0000] {task_command.py:410} INFO - Running <TaskInstance: kafka_to_postgres.consume_and_save manual__2025-09-01T13:35:19.051238+00:00 [running]> on host 09bf1d5cefac
[2025-09-01T13:36:12.785+0000] {taskinstance.py:1547} INFO - Exporting env vars: AIRFLOW_CTX_DAG_OWNER='***' AIRFLOW_CTX_DAG_ID='kafka_to_postgres' AIRFLOW_CTX_TASK_ID='consume_and_save' AIRFLOW_CTX_EXECUTION_DATE='2025-09-01T13:35:19.051238+00:00' AIRFLOW_CTX_TRY_NUMBER='2' AIRFLOW_CTX_DAG_RUN_ID='manual__2025-09-01T13:35:19.051238+00:00'
[2025-09-01T13:36:16.838+0000] {conn.py:1521} WARNING - DNS lookup failed for kafka:9092, exception was [Errno -2] Name or service not known. Is your advertised.listeners (called advertised.host.name before Kafka 9) correct and resolvable?
[2025-09-01T13:36:16.840+0000] {conn.py:324} ERROR - <BrokerConnection client_id=kafka-python-2.2.15, node_id=bootstrap-0 host=kafka:9092 <connecting> [unspecified None]>: DNS lookup failed for kafka:9092 (AddressFamily.AF_UNSPEC)
[2025-09-01T13:36:16.842+0000] {conn.py:945} ERROR - <BrokerConnection client_id=kafka-python-2.2.15, node_id=bootstrap-0 host=kafka:9092 <connecting> [unspecified None]>: Closing connection. KafkaConnectionError: DNS failure
[2025-09-01T13:36:16.845+0000] {taskinstance.py:1824} ERROR - Task failed with exception
Traceback (most recent call last):
  File "/home/airflow/.local/lib/python3.7/site-packages/airflow/operators/python.py", line 181, in execute
    return_value = self.execute_callable()
  File "/home/airflow/.local/lib/python3.7/site-packages/airflow/operators/python.py", line 198, in execute_callable
    return self.python_callable(*self.op_args, **self.op_kwargs)
  File "/opt/airflow/dags/dags_utils.py", line 26, in consume_and_save
    group_id="airflow_consumer"
  File "/home/airflow/.local/lib/python3.7/site-packages/kafka/consumer/group.py", line 387, in __init__
    self._client = self.config['kafka_client'](metrics=self._metrics, **self.config)
  File "/home/airflow/.local/lib/python3.7/site-packages/kafka/client_async.py", line 262, in __init__
    self.config['api_version'] = self.check_version()
  File "/home/airflow/.local/lib/python3.7/site-packages/kafka/client_async.py", line 1074, in check_version
    raise Errors.NoBrokersAvailable()
kafka.errors.NoBrokersAvailable: NoBrokersAvailable
[2025-09-01T13:36:16.894+0000] {taskinstance.py:1350} INFO - Marking task as UP_FOR_RETRY. dag_id=kafka_to_postgres, task_id=consume_and_save, execution_date=20250901T133519, start_date=20250901T133609, end_date=20250901T133616
[2025-09-01T13:36:16.929+0000] {standard_task_runner.py:109} ERROR - Failed to execute job 24 for task consume_and_save (NoBrokersAvailable; 451)
[2025-09-01T13:36:16.978+0000] {local_task_job_runner.py:225} INFO - Task exited with return code 1
[2025-09-01T13:36:17.023+0000] {taskinstance.py:2653} INFO - 0 downstream tasks scheduled from follow-on schedule check
