[2025-09-14T19:38:18.608+0000] {taskinstance.py:1103} INFO - Dependencies all met for dep_context=non-requeueable deps ti=<TaskInstance: raw_to_dds_enhanced.load_orders manual__2025-09-14T19:33:26.363734+00:00 [queued]>
[2025-09-14T19:38:18.632+0000] {taskinstance.py:1103} INFO - Dependencies all met for dep_context=requeueable deps ti=<TaskInstance: raw_to_dds_enhanced.load_orders manual__2025-09-14T19:33:26.363734+00:00 [queued]>
[2025-09-14T19:38:18.633+0000] {taskinstance.py:1308} INFO - Starting attempt 3 of 5
[2025-09-14T19:38:18.672+0000] {taskinstance.py:1327} INFO - Executing <Task(PythonOperator): load_orders> on 2025-09-14 19:33:26.363734+00:00
[2025-09-14T19:38:18.707+0000] {standard_task_runner.py:57} INFO - Started process 11104 to run task
[2025-09-14T19:38:18.751+0000] {standard_task_runner.py:84} INFO - Running: ['***', 'tasks', 'run', 'raw_to_dds_enhanced', 'load_orders', 'manual__2025-09-14T19:33:26.363734+00:00', '--job-id', '212', '--raw', '--subdir', 'DAGS_FOLDER/raw_to_dds.py', '--cfg-path', '/tmp/tmpo089s3uz']
[2025-09-14T19:38:18.783+0000] {standard_task_runner.py:85} INFO - Job 212: Subtask load_orders
[2025-09-14T19:38:18.988+0000] {logging_mixin.py:150} WARNING - /home/***/.local/lib/python3.7/site-packages/***/settings.py:195 DeprecationWarning: The sql_alchemy_conn option in [core] has been moved to the sql_alchemy_conn option in [database] - the old setting has been used, but please update your config.
[2025-09-14T19:38:19.240+0000] {task_command.py:410} INFO - Running <TaskInstance: raw_to_dds_enhanced.load_orders manual__2025-09-14T19:33:26.363734+00:00 [running]> on host 3deaa5b4a23c
[2025-09-14T19:38:19.921+0000] {taskinstance.py:1547} INFO - Exporting env vars: AIRFLOW_CTX_DAG_OWNER='***' AIRFLOW_CTX_DAG_ID='raw_to_dds_enhanced' AIRFLOW_CTX_TASK_ID='load_orders' AIRFLOW_CTX_EXECUTION_DATE='2025-09-14T19:33:26.363734+00:00' AIRFLOW_CTX_TRY_NUMBER='3' AIRFLOW_CTX_DAG_RUN_ID='manual__2025-09-14T19:33:26.363734+00:00'
[2025-09-14T19:38:20.325+0000] {taskinstance.py:1824} ERROR - Task failed with exception
Traceback (most recent call last):
  File "/home/airflow/.local/lib/python3.7/site-packages/airflow/operators/python.py", line 181, in execute
    return_value = self.execute_callable()
  File "/home/airflow/.local/lib/python3.7/site-packages/airflow/operators/python.py", line 198, in execute_callable
    return self.python_callable(*self.op_args, **self.op_kwargs)
  File "/opt/airflow/dags/raw_to_dds.py", line 177, in load_orders_from_events
    conn, params=(tuple(missing_users_native),))['user_id'].tolist()
  File "/home/airflow/.local/lib/python3.7/site-packages/pandas/io/sql.py", line 634, in read_sql
    chunksize=chunksize,
  File "/home/airflow/.local/lib/python3.7/site-packages/pandas/io/sql.py", line 1579, in read_query
    result = self.execute(*args)
  File "/home/airflow/.local/lib/python3.7/site-packages/pandas/io/sql.py", line 1424, in execute
    return self.connectable.execution_options().execute(*args, **kwargs)
  File "/home/airflow/.local/lib/python3.7/site-packages/sqlalchemy/engine/base.py", line 1375, in execute
    future=False,
  File "/home/airflow/.local/lib/python3.7/site-packages/sqlalchemy/engine/base.py", line 1681, in _exec_driver_sql
    distilled_parameters,
  File "/home/airflow/.local/lib/python3.7/site-packages/sqlalchemy/engine/base.py", line 1954, in _execute_context
    e, statement, parameters, cursor, context
  File "/home/airflow/.local/lib/python3.7/site-packages/sqlalchemy/engine/base.py", line 2138, in _handle_dbapi_exception
    util.raise_(exc_info[1], with_traceback=exc_info[2])
  File "/home/airflow/.local/lib/python3.7/site-packages/sqlalchemy/util/compat.py", line 211, in raise_
    raise exception
  File "/home/airflow/.local/lib/python3.7/site-packages/sqlalchemy/engine/base.py", line 1911, in _execute_context
    cursor, statement, parameters, context
  File "/home/airflow/.local/lib/python3.7/site-packages/sqlalchemy/engine/default.py", line 736, in do_execute
    cursor.execute(statement, parameters)
TypeError: not all arguments converted during string formatting
[2025-09-14T19:38:20.431+0000] {taskinstance.py:1350} INFO - Marking task as UP_FOR_RETRY. dag_id=raw_to_dds_enhanced, task_id=load_orders, execution_date=20250914T193326, start_date=20250914T193818, end_date=20250914T193820
[2025-09-14T19:38:20.488+0000] {standard_task_runner.py:109} ERROR - Failed to execute job 212 for task load_orders (not all arguments converted during string formatting; 11104)
[2025-09-14T19:38:20.560+0000] {local_task_job_runner.py:225} INFO - Task exited with return code 1
[2025-09-14T19:38:20.625+0000] {taskinstance.py:2653} INFO - 0 downstream tasks scheduled from follow-on schedule check
