[2025-09-14T19:21:49.440+0000] {logging_mixin.py:150} WARNING - /home/***/.local/lib/python3.7/site-packages/***/utils/sqlalchemy.py:124 DeprecationWarning: The sql_alchemy_conn option in [core] has been moved to the sql_alchemy_conn option in [database] - the old setting has been used, but please update your config.
[2025-09-14T19:21:49.504+0000] {taskinstance.py:1103} INFO - Dependencies all met for dep_context=non-requeueable deps ti=<TaskInstance: raw_to_dds_enhanced.load_orders scheduled__2025-09-14T18:09:37.053070+00:00 [queued]>
[2025-09-14T19:21:49.536+0000] {taskinstance.py:1103} INFO - Dependencies all met for dep_context=requeueable deps ti=<TaskInstance: raw_to_dds_enhanced.load_orders scheduled__2025-09-14T18:09:37.053070+00:00 [queued]>
[2025-09-14T19:21:49.539+0000] {taskinstance.py:1308} INFO - Starting attempt 3 of 3
[2025-09-14T19:21:49.659+0000] {taskinstance.py:1327} INFO - Executing <Task(PythonOperator): load_orders> on 2025-09-14 18:09:37.053070+00:00
[2025-09-14T19:21:49.693+0000] {standard_task_runner.py:57} INFO - Started process 9723 to run task
[2025-09-14T19:21:49.700+0000] {standard_task_runner.py:84} INFO - Running: ['***', 'tasks', 'run', 'raw_to_dds_enhanced', 'load_orders', 'scheduled__2025-09-14T18:09:37.053070+00:00', '--job-id', '200', '--raw', '--subdir', 'DAGS_FOLDER/raw_to_dds.py', '--cfg-path', '/tmp/tmpznws1lal']
[2025-09-14T19:21:49.707+0000] {standard_task_runner.py:85} INFO - Job 200: Subtask load_orders
[2025-09-14T19:21:49.749+0000] {logging_mixin.py:150} WARNING - /home/***/.local/lib/python3.7/site-packages/***/settings.py:195 DeprecationWarning: The sql_alchemy_conn option in [core] has been moved to the sql_alchemy_conn option in [database] - the old setting has been used, but please update your config.
[2025-09-14T19:21:49.924+0000] {task_command.py:410} INFO - Running <TaskInstance: raw_to_dds_enhanced.load_orders scheduled__2025-09-14T18:09:37.053070+00:00 [running]> on host 3deaa5b4a23c
[2025-09-14T19:21:49.982+0000] {logging_mixin.py:150} WARNING - /home/***/.local/lib/python3.7/site-packages/***/utils/sqlalchemy.py:124 DeprecationWarning: The sql_alchemy_conn option in [core] has been moved to the sql_alchemy_conn option in [database] - the old setting has been used, but please update your config.
[2025-09-14T19:21:50.298+0000] {taskinstance.py:1547} INFO - Exporting env vars: AIRFLOW_CTX_DAG_OWNER='***' AIRFLOW_CTX_DAG_ID='raw_to_dds_enhanced' AIRFLOW_CTX_TASK_ID='load_orders' AIRFLOW_CTX_EXECUTION_DATE='2025-09-14T18:09:37.053070+00:00' AIRFLOW_CTX_TRY_NUMBER='3' AIRFLOW_CTX_DAG_RUN_ID='scheduled__2025-09-14T18:09:37.053070+00:00'
[2025-09-14T19:21:50.655+0000] {taskinstance.py:1824} ERROR - Task failed with exception
Traceback (most recent call last):
  File "/home/airflow/.local/lib/python3.7/site-packages/airflow/operators/python.py", line 181, in execute
    return_value = self.execute_callable()
  File "/home/airflow/.local/lib/python3.7/site-packages/airflow/operators/python.py", line 198, in execute_callable
    return self.python_callable(*self.op_args, **self.op_kwargs)
  File "/opt/airflow/dags/raw_to_dds.py", line 147, in load_orders_from_events
    cur.execute(order_sql, (row["order_id"], row["user_id"], row["order_ts"], row["total_usd"]))
psycopg2.errors.ForeignKeyViolation: insert or update on table "orders" violates foreign key constraint "orders_user_id_fkey"
DETAIL:  Key (user_id)=(4738) is not present in table "users".

[2025-09-14T19:21:50.705+0000] {taskinstance.py:1350} INFO - Marking task as FAILED. dag_id=raw_to_dds_enhanced, task_id=load_orders, execution_date=20250914T180937, start_date=20250914T192149, end_date=20250914T192150
[2025-09-14T19:21:50.709+0000] {logging_mixin.py:150} WARNING - /home/***/.local/lib/python3.7/site-packages/***/utils/context.py:205 AirflowContextDeprecationWarning: Accessing 'execution_date' from the template is deprecated and will be removed in a future version. Please use 'data_interval_start' or 'logical_date' instead.
[2025-09-14T19:21:51.596+0000] {standard_task_runner.py:109} ERROR - Failed to execute job 200 for task load_orders (insert or update on table "orders" violates foreign key constraint "orders_user_id_fkey"
DETAIL:  Key (user_id)=(4738) is not present in table "users".
; 9723)
[2025-09-14T19:21:51.641+0000] {local_task_job_runner.py:225} INFO - Task exited with return code 1
[2025-09-14T19:21:51.679+0000] {taskinstance.py:2653} INFO - 0 downstream tasks scheduled from follow-on schedule check
