[2025-09-14T12:19:46.648+0000] {taskinstance.py:1103} INFO - Dependencies all met for dep_context=non-requeueable deps ti=<TaskInstance: raw_to_dds_enhanced.upsert_users manual__2025-09-14T12:09:17.333529+00:00 [queued]>
[2025-09-14T12:19:46.678+0000] {taskinstance.py:1103} INFO - Dependencies all met for dep_context=requeueable deps ti=<TaskInstance: raw_to_dds_enhanced.upsert_users manual__2025-09-14T12:09:17.333529+00:00 [queued]>
[2025-09-14T12:19:46.679+0000] {taskinstance.py:1308} INFO - Starting attempt 3 of 3
[2025-09-14T12:19:46.742+0000] {taskinstance.py:1327} INFO - Executing <Task(PythonOperator): upsert_users> on 2025-09-14 12:09:17.333529+00:00
[2025-09-14T12:19:46.795+0000] {standard_task_runner.py:57} INFO - Started process 3817 to run task
[2025-09-14T12:19:46.803+0000] {standard_task_runner.py:84} INFO - Running: ['***', 'tasks', 'run', 'raw_to_dds_enhanced', 'upsert_users', 'manual__2025-09-14T12:09:17.333529+00:00', '--job-id', '90', '--raw', '--subdir', 'DAGS_FOLDER/raw_to_dds.py', '--cfg-path', '/tmp/tmpbok46vbu']
[2025-09-14T12:19:46.809+0000] {standard_task_runner.py:85} INFO - Job 90: Subtask upsert_users
[2025-09-14T12:19:46.877+0000] {logging_mixin.py:150} WARNING - /home/***/.local/lib/python3.7/site-packages/***/settings.py:195 DeprecationWarning: The sql_alchemy_conn option in [core] has been moved to the sql_alchemy_conn option in [database] - the old setting has been used, but please update your config.
[2025-09-14T12:19:47.034+0000] {task_command.py:410} INFO - Running <TaskInstance: raw_to_dds_enhanced.upsert_users manual__2025-09-14T12:09:17.333529+00:00 [running]> on host 3deaa5b4a23c
[2025-09-14T12:19:47.763+0000] {taskinstance.py:1547} INFO - Exporting env vars: AIRFLOW_CTX_DAG_OWNER='***' AIRFLOW_CTX_DAG_ID='raw_to_dds_enhanced' AIRFLOW_CTX_TASK_ID='upsert_users' AIRFLOW_CTX_EXECUTION_DATE='2025-09-14T12:09:17.333529+00:00' AIRFLOW_CTX_TRY_NUMBER='3' AIRFLOW_CTX_DAG_RUN_ID='manual__2025-09-14T12:09:17.333529+00:00'
[2025-09-14T12:19:48.255+0000] {taskinstance.py:1824} ERROR - Task failed with exception
Traceback (most recent call last):
  File "/home/airflow/.local/lib/python3.7/site-packages/airflow/operators/python.py", line 181, in execute
    return_value = self.execute_callable()
  File "/home/airflow/.local/lib/python3.7/site-packages/airflow/operators/python.py", line 198, in execute_callable
    return self.python_callable(*self.op_args, **self.op_kwargs)
  File "/opt/airflow/dags/raw_to_dds.py", line 62, in upsert_users_from_raw
    birth_date = COALESCE(EXCLUDED.birth_date, dds.users.birth_date),
psycopg2.errors.CheckViolation: new row for relation "users" violates check constraint "users_gender_check"
DETAIL:  Failing row contains (4567, Jennifer Gordon, utaylor@example.net, 1957-10-05, other, Манастир Рача, Serbia).

[2025-09-14T12:19:48.351+0000] {taskinstance.py:1350} INFO - Marking task as FAILED. dag_id=raw_to_dds_enhanced, task_id=upsert_users, execution_date=20250914T120917, start_date=20250914T121946, end_date=20250914T121948
[2025-09-14T12:19:48.359+0000] {logging_mixin.py:150} WARNING - /home/***/.local/lib/python3.7/site-packages/***/utils/context.py:205 AirflowContextDeprecationWarning: Accessing 'execution_date' from the template is deprecated and will be removed in a future version. Please use 'data_interval_start' or 'logical_date' instead.
[2025-09-14T12:19:51.099+0000] {standard_task_runner.py:109} ERROR - Failed to execute job 90 for task upsert_users (new row for relation "users" violates check constraint "users_gender_check"
DETAIL:  Failing row contains (4567, Jennifer Gordon, utaylor@example.net, 1957-10-05, other, Манастир Рача, Serbia).
; 3817)
[2025-09-14T12:19:51.154+0000] {local_task_job_runner.py:225} INFO - Task exited with return code 1
[2025-09-14T12:19:51.369+0000] {taskinstance.py:2653} INFO - 0 downstream tasks scheduled from follow-on schedule check
