[2025-09-16T18:41:35.326+0000] {logging_mixin.py:150} WARNING - /home/***/.local/lib/python3.7/site-packages/***/utils/sqlalchemy.py:124 DeprecationWarning: The sql_alchemy_conn option in [core] has been moved to the sql_alchemy_conn option in [database] - the old setting has been used, but please update your config.
[2025-09-16T18:41:35.702+0000] {taskinstance.py:1103} INFO - Dependencies all met for dep_context=non-requeueable deps ti=<TaskInstance: generate_events_minutely.produce_entities_and_events scheduled__2025-09-16T18:39:58.052315+00:00 [queued]>
[2025-09-16T18:41:35.739+0000] {taskinstance.py:1103} INFO - Dependencies all met for dep_context=requeueable deps ti=<TaskInstance: generate_events_minutely.produce_entities_and_events scheduled__2025-09-16T18:39:58.052315+00:00 [queued]>
[2025-09-16T18:41:35.740+0000] {taskinstance.py:1308} INFO - Starting attempt 1 of 2
[2025-09-16T18:41:35.794+0000] {taskinstance.py:1327} INFO - Executing <Task(PythonOperator): produce_entities_and_events> on 2025-09-16 18:39:58.052315+00:00
[2025-09-16T18:41:35.814+0000] {standard_task_runner.py:57} INFO - Started process 3681 to run task
[2025-09-16T18:41:35.821+0000] {standard_task_runner.py:84} INFO - Running: ['***', 'tasks', 'run', 'generate_events_minutely', 'produce_entities_and_events', 'scheduled__2025-09-16T18:39:58.052315+00:00', '--job-id', '715', '--raw', '--subdir', 'DAGS_FOLDER/generator_dag.py', '--cfg-path', '/tmp/tmpsieqs7ij']
[2025-09-16T18:41:35.827+0000] {standard_task_runner.py:85} INFO - Job 715: Subtask produce_entities_and_events
[2025-09-16T18:41:35.891+0000] {logging_mixin.py:150} WARNING - /home/***/.local/lib/python3.7/site-packages/***/settings.py:195 DeprecationWarning: The sql_alchemy_conn option in [core] has been moved to the sql_alchemy_conn option in [database] - the old setting has been used, but please update your config.
[2025-09-16T18:41:36.024+0000] {task_command.py:410} INFO - Running <TaskInstance: generate_events_minutely.produce_entities_and_events scheduled__2025-09-16T18:39:58.052315+00:00 [running]> on host d6e2a7c8b3ee
[2025-09-16T18:41:36.196+0000] {logging_mixin.py:150} WARNING - /home/***/.local/lib/python3.7/site-packages/***/utils/sqlalchemy.py:124 DeprecationWarning: The sql_alchemy_conn option in [core] has been moved to the sql_alchemy_conn option in [database] - the old setting has been used, but please update your config.
[2025-09-16T18:41:36.420+0000] {taskinstance.py:1547} INFO - Exporting env vars: AIRFLOW_CTX_DAG_OWNER='***' AIRFLOW_CTX_DAG_ID='generate_events_minutely' AIRFLOW_CTX_TASK_ID='produce_entities_and_events' AIRFLOW_CTX_EXECUTION_DATE='2025-09-16T18:39:58.052315+00:00' AIRFLOW_CTX_TRY_NUMBER='1' AIRFLOW_CTX_DAG_RUN_ID='scheduled__2025-09-16T18:39:58.052315+00:00'
[2025-09-16T18:41:39.956+0000] {logging_mixin.py:150} INFO - [DEBUG] Kafka connection error: [Errno -2] Name or service not known
[2025-09-16T18:41:39.964+0000] {generator_dag.py:37} ERROR - Producer failed
Traceback (most recent call last):
  File "/opt/airflow/dags/generator_dag.py", line 33, in produce_task
    sent = produce_batch(send_count_users=1, events_per_user=2, broker=KAFKA_BROKER)
  File "/opt/airflow/dags/generator.py", line 256, in produce_batch
    raise RuntimeError(f"Kafka broker {broker} недоступен")
RuntimeError: Kafka broker kafka:29092 недоступен
[2025-09-16T18:41:40.004+0000] {taskinstance.py:1824} ERROR - Task failed with exception
Traceback (most recent call last):
  File "/home/airflow/.local/lib/python3.7/site-packages/airflow/operators/python.py", line 181, in execute
    return_value = self.execute_callable()
  File "/home/airflow/.local/lib/python3.7/site-packages/airflow/operators/python.py", line 198, in execute_callable
    return self.python_callable(*self.op_args, **self.op_kwargs)
  File "/opt/airflow/dags/generator_dag.py", line 33, in produce_task
    sent = produce_batch(send_count_users=1, events_per_user=2, broker=KAFKA_BROKER)
  File "/opt/airflow/dags/generator.py", line 256, in produce_batch
    raise RuntimeError(f"Kafka broker {broker} недоступен")
RuntimeError: Kafka broker kafka:29092 недоступен
[2025-09-16T18:41:40.026+0000] {taskinstance.py:1350} INFO - Marking task as UP_FOR_RETRY. dag_id=generate_events_minutely, task_id=produce_entities_and_events, execution_date=20250916T183958, start_date=20250916T184135, end_date=20250916T184140
[2025-09-16T18:41:40.054+0000] {standard_task_runner.py:109} ERROR - Failed to execute job 715 for task produce_entities_and_events (Kafka broker kafka:29092 недоступен; 3681)
[2025-09-16T18:41:40.076+0000] {local_task_job_runner.py:225} INFO - Task exited with return code 1
[2025-09-16T18:41:40.107+0000] {taskinstance.py:2653} INFO - 0 downstream tasks scheduled from follow-on schedule check
