[2025-09-14T13:51:03.624+0000] {logging_mixin.py:150} WARNING - /home/***/.local/lib/python3.7/site-packages/***/utils/sqlalchemy.py:124 DeprecationWarning: The sql_alchemy_conn option in [core] has been moved to the sql_alchemy_conn option in [database] - the old setting has been used, but please update your config.
[2025-09-14T13:51:03.645+0000] {taskinstance.py:1103} INFO - Dependencies all met for dep_context=non-requeueable deps ti=<TaskInstance: raw_to_dds_enhanced.load_products scheduled__2025-09-14T12:40:16.296314+00:00 [queued]>
[2025-09-14T13:51:03.667+0000] {taskinstance.py:1103} INFO - Dependencies all met for dep_context=requeueable deps ti=<TaskInstance: raw_to_dds_enhanced.load_products scheduled__2025-09-14T12:40:16.296314+00:00 [queued]>
[2025-09-14T13:51:03.668+0000] {taskinstance.py:1308} INFO - Starting attempt 3 of 3
[2025-09-14T13:51:03.701+0000] {taskinstance.py:1327} INFO - Executing <Task(PythonOperator): load_products> on 2025-09-14 12:40:16.296314+00:00
[2025-09-14T13:51:03.725+0000] {standard_task_runner.py:57} INFO - Started process 11202 to run task
[2025-09-14T13:51:03.736+0000] {standard_task_runner.py:84} INFO - Running: ['***', 'tasks', 'run', 'raw_to_dds_enhanced', 'load_products', 'scheduled__2025-09-14T12:40:16.296314+00:00', '--job-id', '147', '--raw', '--subdir', 'DAGS_FOLDER/raw_to_dds.py', '--cfg-path', '/tmp/tmp8jzcnc50']
[2025-09-14T13:51:03.739+0000] {standard_task_runner.py:85} INFO - Job 147: Subtask load_products
[2025-09-14T13:51:04.049+0000] {logging_mixin.py:150} WARNING - /home/***/.local/lib/python3.7/site-packages/***/settings.py:195 DeprecationWarning: The sql_alchemy_conn option in [core] has been moved to the sql_alchemy_conn option in [database] - the old setting has been used, but please update your config.
[2025-09-14T13:51:04.877+0000] {task_command.py:410} INFO - Running <TaskInstance: raw_to_dds_enhanced.load_products scheduled__2025-09-14T12:40:16.296314+00:00 [running]> on host 3deaa5b4a23c
[2025-09-14T13:51:05.246+0000] {logging_mixin.py:150} WARNING - /home/***/.local/lib/python3.7/site-packages/***/utils/sqlalchemy.py:124 DeprecationWarning: The sql_alchemy_conn option in [core] has been moved to the sql_alchemy_conn option in [database] - the old setting has been used, but please update your config.
[2025-09-14T13:51:05.799+0000] {taskinstance.py:1547} INFO - Exporting env vars: AIRFLOW_CTX_DAG_OWNER='***' AIRFLOW_CTX_DAG_ID='raw_to_dds_enhanced' AIRFLOW_CTX_TASK_ID='load_products' AIRFLOW_CTX_EXECUTION_DATE='2025-09-14T12:40:16.296314+00:00' AIRFLOW_CTX_TRY_NUMBER='3' AIRFLOW_CTX_DAG_RUN_ID='scheduled__2025-09-14T12:40:16.296314+00:00'
[2025-09-14T13:51:05.862+0000] {taskinstance.py:1824} ERROR - Task failed with exception
Traceback (most recent call last):
  File "/home/airflow/.local/lib/python3.7/site-packages/sqlalchemy/engine/base.py", line 1911, in _execute_context
    cursor, statement, parameters, context
  File "/home/airflow/.local/lib/python3.7/site-packages/sqlalchemy/engine/default.py", line 736, in do_execute
    cursor.execute(statement, parameters)
psycopg2.errors.UndefinedColumn: column "category" does not exist
LINE 3:         SELECT DISTINCT category
                                ^
HINT:  Perhaps you meant to reference the column "categories.category_id".


The above exception was the direct cause of the following exception:

Traceback (most recent call last):
  File "/home/airflow/.local/lib/python3.7/site-packages/airflow/operators/python.py", line 181, in execute
    return_value = self.execute_callable()
  File "/home/airflow/.local/lib/python3.7/site-packages/airflow/operators/python.py", line 198, in execute_callable
    return self.python_callable(*self.op_args, **self.op_kwargs)
  File "/opt/airflow/dags/raw_to_dds.py", line 164, in load_products_and_categories
    conn.execute(query_cat)
  File "/home/airflow/.local/lib/python3.7/site-packages/sqlalchemy/engine/base.py", line 1375, in execute
    future=False,
  File "/home/airflow/.local/lib/python3.7/site-packages/sqlalchemy/engine/base.py", line 1681, in _exec_driver_sql
    distilled_parameters,
  File "/home/airflow/.local/lib/python3.7/site-packages/sqlalchemy/engine/base.py", line 1954, in _execute_context
    e, statement, parameters, cursor, context
  File "/home/airflow/.local/lib/python3.7/site-packages/sqlalchemy/engine/base.py", line 2135, in _handle_dbapi_exception
    sqlalchemy_exception, with_traceback=exc_info[2], from_=e
  File "/home/airflow/.local/lib/python3.7/site-packages/sqlalchemy/util/compat.py", line 211, in raise_
    raise exception
  File "/home/airflow/.local/lib/python3.7/site-packages/sqlalchemy/engine/base.py", line 1911, in _execute_context
    cursor, statement, parameters, context
  File "/home/airflow/.local/lib/python3.7/site-packages/sqlalchemy/engine/default.py", line 736, in do_execute
    cursor.execute(statement, parameters)
sqlalchemy.exc.ProgrammingError: (psycopg2.errors.UndefinedColumn) column "category" does not exist
LINE 3:         SELECT DISTINCT category
                                ^
HINT:  Perhaps you meant to reference the column "categories.category_id".

[SQL: 
        INSERT INTO dds.categories (category_name)
        SELECT DISTINCT category
        FROM raw.events
        WHERE category IS NOT NULL
        ON CONFLICT (category_name) DO NOTHING;
        ]
(Background on this error at: https://sqlalche.me/e/14/f405)
[2025-09-14T13:51:05.933+0000] {taskinstance.py:1350} INFO - Marking task as FAILED. dag_id=raw_to_dds_enhanced, task_id=load_products, execution_date=20250914T124016, start_date=20250914T135103, end_date=20250914T135105
[2025-09-14T13:51:05.936+0000] {logging_mixin.py:150} WARNING - /home/***/.local/lib/python3.7/site-packages/***/utils/context.py:205 AirflowContextDeprecationWarning: Accessing 'execution_date' from the template is deprecated and will be removed in a future version. Please use 'data_interval_start' or 'logical_date' instead.
[2025-09-14T13:51:06.730+0000] {standard_task_runner.py:109} ERROR - Failed to execute job 147 for task load_products ((psycopg2.errors.UndefinedColumn) column "category" does not exist
LINE 3:         SELECT DISTINCT category
                                ^
HINT:  Perhaps you meant to reference the column "categories.category_id".

[SQL: 
        INSERT INTO dds.categories (category_name)
        SELECT DISTINCT category
        FROM raw.events
        WHERE category IS NOT NULL
        ON CONFLICT (category_name) DO NOTHING;
        ]
(Background on this error at: https://sqlalche.me/e/14/f405); 11202)
[2025-09-14T13:51:06.783+0000] {local_task_job_runner.py:225} INFO - Task exited with return code 1
[2025-09-14T13:51:06.974+0000] {taskinstance.py:2653} INFO - 0 downstream tasks scheduled from follow-on schedule check
