[2025-09-10T13:29:22.247+0000] {taskinstance.py:1103} INFO - Dependencies all met for dep_context=non-requeueable deps ti=<TaskInstance: generate_events.produce_events manual__2025-09-10T13:24:11.072739+00:00 [queued]>
[2025-09-10T13:29:22.272+0000] {taskinstance.py:1103} INFO - Dependencies all met for dep_context=requeueable deps ti=<TaskInstance: generate_events.produce_events manual__2025-09-10T13:24:11.072739+00:00 [queued]>
[2025-09-10T13:29:22.273+0000] {taskinstance.py:1308} INFO - Starting attempt 2 of 2
[2025-09-10T13:29:22.307+0000] {taskinstance.py:1327} INFO - Executing <Task(PythonOperator): produce_events> on 2025-09-10 13:24:11.072739+00:00
[2025-09-10T13:29:22.340+0000] {standard_task_runner.py:57} INFO - Started process 543 to run task
[2025-09-10T13:29:22.370+0000] {standard_task_runner.py:84} INFO - Running: ['***', 'tasks', 'run', 'generate_events', 'produce_events', 'manual__2025-09-10T13:24:11.072739+00:00', '--job-id', '98', '--raw', '--subdir', 'DAGS_FOLDER/generator_dag.py', '--cfg-path', '/tmp/tmpi_7zyf7h']
[2025-09-10T13:29:22.393+0000] {standard_task_runner.py:85} INFO - Job 98: Subtask produce_events
[2025-09-10T13:29:22.529+0000] {logging_mixin.py:150} WARNING - /home/***/.local/lib/python3.7/site-packages/***/settings.py:195 DeprecationWarning: The sql_alchemy_conn option in [core] has been moved to the sql_alchemy_conn option in [database] - the old setting has been used, but please update your config.
[2025-09-10T13:29:22.606+0000] {task_command.py:410} INFO - Running <TaskInstance: generate_events.produce_events manual__2025-09-10T13:24:11.072739+00:00 [running]> on host c905ba028b15
[2025-09-10T13:29:22.768+0000] {taskinstance.py:1547} INFO - Exporting env vars: AIRFLOW_CTX_DAG_OWNER='***' AIRFLOW_CTX_DAG_ID='generate_events' AIRFLOW_CTX_TASK_ID='produce_events' AIRFLOW_CTX_EXECUTION_DATE='2025-09-10T13:24:11.072739+00:00' AIRFLOW_CTX_TRY_NUMBER='2' AIRFLOW_CTX_DAG_RUN_ID='manual__2025-09-10T13:24:11.072739+00:00'
[2025-09-10T13:29:22.771+0000] {client_async.py:278} WARNING - Configured api_version (2, 0, 2) not supported; using (2, 0)
[2025-09-10T13:29:22.782+0000] {conn.py:397} INFO - <BrokerConnection client_id=kafka-python-2.2.15, node_id=bootstrap-0 host=localhost:9092 <connecting> [IPv6 ('::1', 9092, 0, 0)]>: connecting to localhost:9092 [('::1', 9092, 0, 0) IPv6]
[2025-09-10T13:29:22.786+0000] {conn.py:430} ERROR - <BrokerConnection client_id=kafka-python-2.2.15, node_id=bootstrap-0 host=localhost:9092 <connecting> [IPv6 ('::1', 9092, 0, 0)]>: Connect attempt returned error 111. Disconnecting.
[2025-09-10T13:29:22.787+0000] {conn.py:945} ERROR - <BrokerConnection client_id=kafka-python-2.2.15, node_id=bootstrap-0 host=localhost:9092 <connecting> [IPv6 ('::1', 9092, 0, 0)]>: Closing connection. KafkaConnectionError: 111 ECONNREFUSED
[2025-09-10T13:29:22.788+0000] {conn.py:397} INFO - <BrokerConnection client_id=kafka-python-2.2.15, node_id=bootstrap-0 host=localhost:9092 <connecting> [IPv4 ('127.0.0.1', 9092)]>: connecting to localhost:9092 [('127.0.0.1', 9092) IPv4]
[2025-09-10T13:29:22.790+0000] {conn.py:430} ERROR - <BrokerConnection client_id=kafka-python-2.2.15, node_id=bootstrap-0 host=localhost:9092 <connecting> [IPv4 ('127.0.0.1', 9092)]>: Connect attempt returned error 111. Disconnecting.
[2025-09-10T13:29:22.790+0000] {conn.py:945} ERROR - <BrokerConnection client_id=kafka-python-2.2.15, node_id=bootstrap-0 host=localhost:9092 <connecting> [IPv4 ('127.0.0.1', 9092)]>: Closing connection. KafkaConnectionError: 111 ECONNREFUSED
[2025-09-10T13:29:22.793+0000] {logging_mixin.py:150} INFO - [DEBUG] Kafka connection error: KafkaConnectionError: Connection to bootstrap-0 failed.
[2025-09-10T13:29:22.793+0000] {taskinstance.py:1824} ERROR - Task failed with exception
Traceback (most recent call last):
  File "/home/airflow/.local/lib/python3.7/site-packages/airflow/operators/python.py", line 181, in execute
    return_value = self.execute_callable()
  File "/home/airflow/.local/lib/python3.7/site-packages/airflow/operators/python.py", line 198, in execute_callable
    return self.python_callable(*self.op_args, **self.op_kwargs)
  File "/opt/airflow/dags/generator_dag.py", line 17, in produce_events
    raise RuntimeError(f"Kafka broker {KAFKA_BROKER} недоступен")
RuntimeError: Kafka broker kafka:29092 недоступен
[2025-09-10T13:29:22.821+0000] {taskinstance.py:1350} INFO - Marking task as FAILED. dag_id=generate_events, task_id=produce_events, execution_date=20250910T132411, start_date=20250910T132922, end_date=20250910T132922
[2025-09-10T13:29:22.848+0000] {standard_task_runner.py:109} ERROR - Failed to execute job 98 for task produce_events (Kafka broker kafka:29092 недоступен; 543)
[2025-09-10T13:29:22.874+0000] {local_task_job_runner.py:225} INFO - Task exited with return code 1
[2025-09-10T13:29:22.915+0000] {taskinstance.py:2653} INFO - 0 downstream tasks scheduled from follow-on schedule check
